https://github.com/sonata-nfv/son-examples/tree/master/service-projects/sonata-ovs-user-service-emu

Nota:
Se puede cambiar el script de inicializacion de la configuracion del OVS para que tenga una IP dentro de 
la misma red del controlador: https://github.com/sonata-nfv/son-examples/blob/master/service-projects/sonata-ovs-user-service-emu/configure_ovs1.sh



son-package --project sonata-ovs-service2-emu -n sonata-demo-service2

curl -i -X POST -F package=@sonata-ovs-service.son http://127.0.0.1:5000/packages
curl -X POST http://127.0.0.1:5000/instantiations -d "{}"
son-emu-cli compute start -d dc2 -n client -i sonatanfv/sonata-iperf3-vnf
son-emu-cli compute start -d dc2 -n server -i sonatanfv/sonata-iperf3-vnf



cd /home/tigarto/Documents/test_diarios_tesis/abril21/test1/topologias


cd /home/tigarto/Documents/test_diarios_tesis/abril21/test1/topologias
sudo python sonata_y1_demo_topology_1.py
containernet> ovs1 ovs-vsctl list-br
containernet> ovs1 ovs-vsctl list-br
containernet> ovs1 ovs-vsctl show  
containernet> ctrl ifconfig
containernet> ovs1 ovs-vsctl set-controller "ovs1" tcp:10.20.0.1:6633
containernet> client ping -c 2 server
containernet> ovs1 ovs-ofctl dump-flows "ovs1"
containernet> ctrl cat ryu.log





cd /home/tigarto/Documents/test_diarios_tesis/abril27/test1/ws-test1/projects
son-package --project sonata-ovs-service2-emu/ -n sonata-ovs-service2



son-access push --upload sonata-demo-service2.son (No se pero no dio)



curl -i -X POST -F package=@sonata-ovs-service2.son http://127.0.0.1:5000/packages
curl -X POST http://127.0.0.1:5000/instantiations -d "{}"

son-emu-cli compute start -d dc2 -n client -i sonatanfv/sonata-iperf3-vnf
son-emu-cli compute start -d dc2 -n server -i sonatanfv/sonata-iperf3-vnf
son-emu-cli compute list

son-emu-cli network add -b -src client:client-eth0 -dst ovs1:port1
son-emu-cli network add -b -src ovs1:port2 -dst server:server-eth0


*************************************************************************************



tigarto@fuck-pc:~/Documents/test-diarios/abril27/test1/ws-test1/projects/sonata-ovs-service2-emu$ sudo son-monitor msd -f msd.yml 
INFO:root:Start son-monitor containers: /tmp/son-monitor/docker
Starting prometheus ... done
Starting grafana    ... done
INFO:root:son-monitor started
parsing msd: msd.yml
INFO:msd:parsing msd: msd.yml
Traceback (most recent call last):
  File "/usr/lib/python3/dist-packages/urllib3/connection.py", line 137, in _new_conn
    (self.host, self.port), self.timeout, **extra_kw)
  File "/usr/lib/python3/dist-packages/urllib3/util/connection.py", line 91, in create_connection
    raise err
  File "/usr/lib/python3/dist-packages/urllib3/util/connection.py", line 81, in create_connection
    sock.connect(sa)
ConnectionRefusedError: [Errno 111] Connection refused

During handling of the above exception, another exception occurred:

Traceback (most recent call last):
  File "/usr/lib/python3/dist-packages/urllib3/connectionpool.py", line 560, in urlopen
    body=body, headers=headers)
  File "/usr/lib/python3/dist-packages/urllib3/connectionpool.py", line 354, in _make_request
    conn.request(method, url, **httplib_request_kw)
  File "/usr/lib/python3.5/http/client.py", line 1106, in request
    self._send_request(method, url, body, headers)
  File "/usr/lib/python3.5/http/client.py", line 1151, in _send_request
    self.endheaders(body)
  File "/usr/lib/python3.5/http/client.py", line 1102, in endheaders
    self._send_output(message_body)
  File "/usr/lib/python3.5/http/client.py", line 934, in _send_output
    self.send(msg)
  File "/usr/lib/python3.5/http/client.py", line 877, in send
    self.connect()
  File "/usr/lib/python3/dist-packages/urllib3/connection.py", line 162, in connect
    conn = self._new_conn()
  File "/usr/lib/python3/dist-packages/urllib3/connection.py", line 146, in _new_conn
    self, "Failed to establish a new connection: %s" % e)
requests.packages.urllib3.exceptions.NewConnectionError: <requests.packages.urllib3.connection.HTTPConnection object at 0x7fed48065f60>: Failed to establish a new connection: [Errno 111] Connection refused

During handling of the above exception, another exception occurred:

Traceback (most recent call last):
  File "/usr/lib/python3/dist-packages/requests/adapters.py", line 376, in send
    timeout=timeout
  File "/usr/lib/python3/dist-packages/urllib3/connectionpool.py", line 610, in urlopen
    _stacktrace=sys.exc_info()[2])
  File "/usr/lib/python3/dist-packages/urllib3/util/retry.py", line 273, in increment
    raise MaxRetryError(_pool, url, error or ResponseError(cause))
requests.packages.urllib3.exceptions.MaxRetryError: HTTPConnectionPool(host='127.0.0.1', port=3000): Max retries exceeded with url: /api/dashboards/db (Caused by NewConnectionError('<requests.packages.urllib3.connection.HTTPConnection object at 0x7fed48065f60>: Failed to establish a new connection: [Errno 111] Connection refused',))

During handling of the above exception, another exception occurred:

Traceback (most recent call last):
  File "/usr/local/bin/son-monitor", line 9, in <module>
    load_entry_point('sonata-cli==3.0', 'console_scripts', 'son-monitor')()
  File "/usr/local/lib/python3.5/dist-packages/sonata_cli-3.0-py3.5.egg/son/monitor/monitor.py", line 516, in main
    print(args.func(args))
  File "/usr/local/lib/python3.5/dist-packages/sonata_cli-3.0-py3.5.egg/son/monitor/monitor.py", line 244, in EMU_command
    ret = getattr(EMU_class, command)(**args)
  File "/usr/local/lib/python3.5/dist-packages/sonata_cli-3.0-py3.5.egg/son/monitor/son_emu.py", line 85, in msd
    return actions[action](**kwargs)
  File "/usr/local/lib/python3.5/dist-packages/sonata_cli-3.0-py3.5.egg/son/monitor/son_emu.py", line 93, in start_msd
    msd_obj.start()
  File "/usr/local/lib/python3.5/dist-packages/sonata_cli-3.0-py3.5.egg/son/monitor/msd.py", line 86, in start
    self.grafana.init_dashboard(title=title, overwrite=overwrite)
  File "/usr/local/lib/python3.5/dist-packages/sonata_cli-3.0-py3.5.egg/son/monitor/grafana_lib.py", line 74, in init_dashboard
    ret = self.session.post(url, json={'dashboard': dashboard, 'overwrite': overwrite})
  File "/usr/lib/python3/dist-packages/requests/sessions.py", line 511, in post
    return self.request('POST', url, data=data, json=json, **kwargs)
  File "/usr/lib/python3/dist-packages/requests/sessions.py", line 468, in request
    resp = self.send(prep, **send_kwargs)
  File "/usr/lib/python3/dist-packages/requests/sessions.py", line 576, in send
    r = adapter.send(request, **kwargs)
  File "/usr/lib/python3/dist-packages/requests/adapters.py", line 437, in send
    raise ConnectionError(e, request=request)
requests.exceptions.ConnectionError: HTTPConnectionPool(host='127.0.0.1', port=3000): Max retries exceeded with url: /api/dashboards/db (Caused by NewConnectionError('<requests.packages.urllib3.connection.HTTPConnection object at 0x7fed48065f60>: Failed to establish a new connection: [Errno 111] Connection refused',))

/////////////////////////////////////////////////////////////////////////////////////////////////////////////////7

  File "/usr/lib/python3/dist-packages/urllib3/util/connection.py", line 81, in create_connection
    sock.connect(sa)
ConnectionRefusedError: [Errno 111] Connection refused



 File "/usr/lib/python3/dist-packages/urllib3/connection.py", line 146, in _new_conn
    self, "Failed to establish a new connection: %s" % e)
requests.packages.urllib3.exceptions.NewConnectionError: <requests.packages.urllib3.connection.HTTPConnection object at 0x7fed48065f60>: Failed to establish a new connection: [Errno 111] Connection refused


  File "/usr/lib/python3/dist-packages/requests/adapters.py", line 437, in send
    raise ConnectionError(e, request=request)
requests.exceptions.ConnectionError: HTTPConnectionPool(host='127.0.0.1', port=3000): Max retries exceeded with url: /api/dashboards/db (Caused by NewConnectionError('<requests.packages.urllib3.connection.HTTPConnection object at 0x7fed48065f60>: Failed to establish a new connection: [Errno 111] Connection refused',))


Posibles respuestas:
https://stackoverflow.com/questions/11585377/python-socket-error-errno-111-connection-refused



